test_0 (__main__.lab2a.test_0)
[Lab 2] - [Investigation 1] - [Part 1] - variables & printing - Test for file creation: ./lab2a.py ... ok
test_1 (__main__.lab2a.test_1)
[Lab 2] - [Investigation 1] - [Part 1] - variables & printing - Test for errors running: ./lab2a.py ... /usr/lib64/python3.12/subprocess.py:822: ResourceWarning: unclosed file <_io.TextIOWrapper name=3 encoding='UTF-8'>
  _cleanup()
ResourceWarning: Enable tracemalloc to get the object allocation traceback
FAIL

======================================================================
FAIL: test_1 (__main__.lab2a.test_1)
[Lab 2] - [Investigation 1] - [Part 1] - variables & printing - Test for errors running: ./lab2a.py
----------------------------------------------------------------------
Traceback (most recent call last):
  File "/home/khushdesai/ops445/lab2/./CheckLab2.py", line 55, in test_1
    self.assertEqual(return_code, 0, msg=error_output)
AssertionError: 1 != 0 : your program exited with an error (HINT: try running your program to see the error)

----------------------------------------------------------------------
Ran 2 tests in 0.169s

FAILED (failures=1)
OPS445 Lab Report - System Information for running ./CheckLab2.py
=================================================================
    User login name: khushdesai
    Git Email: kadesai3@myseneca.ca
    Linux system name: fedora
    Python executable: /usr/bin/python3
    Python version:  3.12.3 (main, Apr 17 2024, 00:00:00) [GCC 14.0.1 20240411 (Red Hat 14.0.1-0)]
    OS Platform: linux
    Working Directory: /home/khushdesai/ops445/lab2
    Start at: Thu May 23 14:53:37 2024
=================================================================
